Workbook

Sheet Sheet1
A1: 海外出張精算書 | F1: =IF(C8="","","["&C8&"]") | R1: （※入力担当記入）
R2: 伝票No.
R3: 参照No.
A4: 原則として帰国後1週間以内に精算してください。
A5: 領収書は海外使用分と国内使用分とを分けて本精算書裏面等に貼付添付し、領収書No.を明記してください。 | R5: （※渡航担当記入）
A6: [2019/10/01～消費税率10％・軽減税率8％対応版] | R6: 命令書No.
A8: 会社 | E8: 社員番号 | I8: 氏名 | O8: 印 | P8: 仮払額 | V8: 円
A9: 負担部門 | E9: 所属
A11: 提出日 | D11: 年 | F11: 月 | H11: 日
A12: 出発日時 | D12: 年 | F12: 月 | H12: 日 | J12: 時 | L12: 分 | M12: ※フライト発着時刻を24時間表記で記入
A13: 帰着日時 | D13: 年 | F13: 月 | H13: 日 | J13: 時 | L13: 分
A16: 精算合計表（自動読込） | L16: 入力担当者確認
A17: 明細コード・費目 | G17: 金額 | L17: 勘定科目 | S17: 税コード | U17: 金額
A18: 海外分 | B18: A： | C18: 出張日当 | G18: =I61 -> 0 | I18: 円 | L18: 71610旅費交通費（海外出張） | S18: - | U18: =G18+G19+G20+G21 -> 0
B19: B： | C19: 海外交通費 | G19: =S88 -> 0 | I19: 円 | L19: 71620旅費交通費（国内出張） | S19: VJ | U19: =G25+G26 -> 0
B20: C： | C20: 海外宿泊費 | G20: =S98 -> 0 | I20: 円 | L20: 72010通信費（国際電話・ネットワーク） | S20: - | U20: =G22 -> 0
B21: D： | C21: 海外雑費 | G21: =S110 -> 0 | I21: 円 | L21: 72020通信費（国内電話・ネットワーク） | S21: VJ | U21: =G27 -> 0
B22: E： | C22: 海外通信費 | G22: =S119 -> 0 | I22: 円 | L22: 72300交際費（一般） | Q22: =LEFTB(L22,5)&S22 -> 72300V2 | S22: V2 | U22: =IF($T$128=Q22,$T$127,0)+IF($T$135=Q22,$T$134,0)+IF($T$142=Q22,$T$141,0)+IF($T$149=Q22,$T$148,0)+IF($T$186=Q22,$T$185,0)+IF($T$192=Q22,$T$191,0)+IF($T$198=Q22,$T$197,0)+IF($T$204=Q22,$T$203,0) -> 0
B23: F： | C23: 海外交際費・会議費 | G23: =T127+T134+T141+T148 -> 0 | I23: 円 | L23: 72300交際費（一般） | Q23: =LEFTB(L23,5)&S23 -> 72300VJ | S23: VJ | U23: =IF($T$128=Q23,$T$127,0)+IF($T$135=Q23,$T$134,0)+IF($T$142=Q23,$T$141,0)+IF($T$149=Q23,$T$148,0)+IF($T$186=Q23,$T$185,0)+IF($T$192=Q23,$T$191,0)+IF($T$198=Q23,$T$197,0)+IF($T$204=Q23,$T$203,0) -> 0
B24: 海外分小計 | G24: =SUM(G18:H23) -> 0 | I24: 円 | L24: 72300交際費（一般） | Q24: =LEFTB(L24,5)&S24 -> 72300VH | S24: VH | U24: =IF($T$128=Q24,$T$127,0)+IF($T$135=Q24,$T$134,0)+IF($T$142=Q24,$T$141,0)+IF($T$149=Q24,$T$148,0)+IF($T$186=Q24,$T$185,0)+IF($T$192=Q24,$T$191,0)+IF($T$198=Q24,$T$197,0)+IF($T$204=Q24,$T$203,0) -> 0
A25: 国内分 | B25: G： | C25: 国内交通費 | G25: =S162 -> 0 | I25: 円 | L25: 72300交際費（一般） | Q25: =LEFTB(L25,5)&S25 -> 72300V1 | S25: V1 | U25: =IF($T$128=Q25,$T$127,0)+IF($T$135=Q25,$T$134,0)+IF($T$142=Q25,$T$141,0)+IF($T$149=Q25,$T$148,0)+IF($T$186=Q25,$T$185,0)+IF($T$192=Q25,$T$191,0)+IF($T$198=Q25,$T$197,0)+IF($T$204=Q25,$T$203,0) -> 0
B26: H： | C26: 国内雑費 | G26: =S170 -> 0 | I26: 円 | L26: 73900会議費（一般） | Q26: =LEFTB(L26,5)&S26 -> 73900V2 | S26: V2 | U26: =IF($T$128=Q26,$T$127,0)+IF($T$135=Q26,$T$134,0)+IF($T$142=Q26,$T$141,0)+IF($T$149=Q26,$T$148,0)+IF($T$186=Q26,$T$185,0)+IF($T$192=Q26,$T$191,0)+IF($T$198=Q26,$T$197,0)+IF($T$204=Q26,$T$203,0) -> 0
B27: I： | C27: 国内通信費 | G27: =S178 -> 0 | I27: 円 | L27: 73900会議費（一般） | Q27: =LEFTB(L27,5)&S27 -> 73900VJ | S27: VJ | U27: =IF($T$128=Q27,$T$127,0)+IF($T$135=Q27,$T$134,0)+IF($T$142=Q27,$T$141,0)+IF($T$149=Q27,$T$148,0)+IF($T$186=Q27,$T$185,0)+IF($T$192=Q27,$T$191,0)+IF($T$198=Q27,$T$197,0)+IF($T$204=Q27,$T$203,0) -> 0
B28: J： | C28: 国内交際費・会議費 | G28: =T185+T191+T197+T203 -> 0 | I28: 円 | L28: 73900会議費（一般） | Q28: =LEFTB(L28,5)&S28 -> 73900VH | S28: VH | U28: =IF($T$128=Q28,$T$127,0)+IF($T$135=Q28,$T$134,0)+IF($T$142=Q28,$T$141,0)+IF($T$149=Q28,$T$148,0)+IF($T$186=Q28,$T$185,0)+IF($T$192=Q28,$T$191,0)+IF($T$198=Q28,$T$197,0)+IF($T$204=Q28,$T$203,0) -> 0
B29: 国内分小計 | G29: =SUM(G25:H28) -> 0 | I29: 円 | L29: 73900会議費（一般） | Q29: =LEFTB(L29,5)&S29 -> 73900V1 | S29: V1 | U29: =IF($T$128=Q29,$T$127,0)+IF($T$135=Q29,$T$134,0)+IF($T$142=Q29,$T$141,0)+IF($T$149=Q29,$T$148,0)+IF($T$186=Q29,$T$185,0)+IF($T$192=Q29,$T$191,0)+IF($T$198=Q29,$T$197,0)+IF($T$204=Q29,$T$203,0) -> 0
A30: 合計金額 | G30: =G24+G29 -> 0 | I30: 円 | L30: 合計 | U30: =SUM(U18:V29) -> 0
A31: 仮払額 | G31: =T8 -> 0 | I31: 円 | L31: 交際費・会議費合計 | U31: =SUM(U22:V29) -> 0
A32: 差引支給額 | G32: =G30-G31 -> 0 | I32: 円
C35: 入力承認 | F35: 入力担当 | J35: 総務人事部長 | M35: 渡航担当 | Q35: 部長 | T35: 課長
A42: 換算レート表 | D42: JPYとの交換時の証票を添付し、下記レート表Noを証票に記入してください
A43: レート表 No. | C43: 両替日付 | E43: 通貨単位 | G43: レート （外貨1＝JPY） | K43: 換算レート表は、外貨購入第一番目の実勢レートを使用。 小数点第4位まで算出してください（小数点第5位で四捨五入）。 左欄のレート入力セルは、小数点第4位までのみ入力できるよう設定されています（小数点第5位以下は入力不可）。 JPYに換算時は小数点第1位で四捨五入し整数化する計算式が実装されています。 レート表を紛失したり、両替を行わなかった等でレート表がない場合には、同行者のレート表コピーを添付するか、自身で出国日のレート表を検索して添付し、換算してください。 海外においてJPY決済した立替金がある場合には、「通貨単位：JPY」「レート：1」と入力設定し、明細書において当該レート表No.を選択して精算ください。
A44: （例） | C44: 43191 | E44: HKD | G44: 14.18
A45: 1
A46: 2
A47: 3
A48: 4
A49: 5
A50: 6
A51: 7
A54: 海外出張旅費精算明細書【出張日当】
...

Sheet Sheet2
A2: （選択してください）
A3: 海外での会議費用（一人5000円以下の飲食代） | B3: 73900会議費（一般）V2 | C3: 73900V2
A4: 海外での飲食接待費（一人5000円超の飲食代） | B4: 72300交際費（一般）V2 | C4: 72300V2
A5: 海外での社内関係者のみの飲食代（金額不問） | B5: 72300交際費（一般）V2 | C5: 72300V2
A6: 海外での飲食接待以外の交際費（手土産等） | B6: 72300交際費（一般）V2 | C6: 72300V2
A8: （選択してください）
A9: 国内での会議費用（一人5000円以下の飲食代）【10％】 | B9: 73900会議費（一般）VJ | C9: 73900VJ
A10: 国内での会議費用（一人5000円以下の飲食代）【8％】 | B10: 73900会議費（一般）VH | C10: 73900VH
A11: 国内での飲食接待費（一人5000円超の飲食代）【10％】 | B11: 72300交際費（一般）VJ | C11: 72300VJ
A12: 国内での飲食接待費（一人5000円超の飲食代）【8％】 | B12: 72300交際費（一般）VH | C12: 72300VH
A13: 国内での社内関係者のみの飲食代（金額不問）【10％】 | B13: 72300交際費（一般）VJ | C13: 72300VJ
A14: 国内での社内関係者のみの飲食代（金額不問）【8％】 | B14: 72300交際費（一般）VH | C14: 72300VH
A15: 国内での飲食接待以外の交際費（手土産等）【10％】 | B15: 72300交際費（一般）VJ | C15: 72300VJ
A16: 国内での飲食接待以外の交際費（手土産等）【8％】 | B16: 72300交際費（一般）VH | C16: 72300VH
A17: 国内での飲食接待以外の交際費（手土産等）【非課税】 | B17: 72300交際費（一般）V1 | C17: 72300V1
